Workbook

Sheet 17 Lists
A1: Dropdown Lists
A2: Controlled vocabulary used throughout the workbook. Edit these lists if the client or firm uses different categories.
A4: Owner | B4: Record Status | C4: Asset Type | D4: Liquidity | E4: Allocation Category | F4: Tax Registration | G4: Priority | H4: Liability Type | I4: Yes / No | J4: Cash Flow Type | K4: Frequency | L4: Goal Area | M4: Policy Type | N4: Estate Status | O4: Document Category | P4: Action Status | Q4: Filing Status | R4: Taxability | S4: Benefit Type | T4: Retirement Source Type | U4: Need Analysis Status | V4: Beneficiary Status
A5: Household | B5: Active | C5: Cash / Bank | D5: Immediate | E5: Cash | F5: Individual | G5: High | H5: Mortgage | I5: Yes | J5: Income | K5: Weekly | L5: Retirement | M5: Life | N5: Complete | O5: Tax | P5: Not Started | Q5: Single | R5: Taxable | S5: 401(k) / 403(b) | T5: Social Security | U5: Adequate | V5: Current
A6: Primary Client | B6: Pending | C6: Taxable Investment | D6: Short-term | E6: Equities | F6: Joint | G6: Medium | H6: HELOC | I6: No | J6: Expense | K6: Biweekly | L6: Education | M6: Disability | N6: Needs Drafting | O6: Income | P6: In Progress | Q6: Married Filing Jointly | R6: Partially Taxable | S6: Pension | T6: Pension | U6: Review Needed | V6: Needs Review
A7: Co-Client / Spouse | B7: Review | C7: Traditional Retirement | D7: Long-term | E7: Fixed Income | F7: Community Property | G7: Low | H7: Auto Loan | I7: TBD | K7: Monthly | L7: Home | M7: Long-Term Care | N7: Needs Update | O7: Investments | P7: Waiting on Client | Q7: Married Filing Separately | R7: Tax-Free | S7: HSA | T7: Annuity | U7: Gap Identified | V7: Missing
A8: Joint | B8: Closed | C8: Roth Retirement | D8: Illiquid | E8: Real Estate | F8: Revocable Trust | H8: Student Loan | K8: Quarterly | L8: Major Purchase | M8: Health | N8: Not Started | O8: Retirement | P8: Waiting on Advisor | Q8: Head of Household | R8: Pre-Tax | S8: FSA | T8: Retirement Account Withdrawal | U8: Quote Pending | V8: Not Applicable
A9: Trust | B9: Inactive | C9: HSA | E9: Alternatives | F9: Irrevocable Trust | H9: Credit Card | K9: Annual | L9: Debt Paydown | M9: Auto | N9: Unknown | O9: Insurance | P9: Complete | Q9: Qualifying Surviving Spouse | R9: After-Tax | S9: Deferred Compensation | T9: Rental Income | U9: Declined
A10: Business | B10: N/A | C10: 529 / Education | E10: Business | F10: Traditional IRA | H10: Personal Loan | K10: One-Time | L10: Legacy | M10: Homeowners | O10: Debt | P10: Deferred | R10: Unknown | S10: Stock Options / RSUs | T10: Business Income | U10: Unknown
A11: Child | C11: Real Estate | E11: Other | F11: Roth IRA | H11: Business Debt | L11: Emergency Fund | M11: Umbrella | O11: Estate | S11: Health Insurance | T11: Part-Time Work
A12: Other | C12: Business Interest | F12: 401(k) / 403(b) | H12: Tax Debt | L12: Tax | M12: Business | O12: Real Estate | S12: Disability | T12: Other
C13: Personal Property | F13: SEP / SIMPLE | H13: Other Liability | L13: Insurance | M13: Other | O13: Business | S13: Life Insurance
C14: Alternative / Crypto | F14: HSA | L14: Other | O14: Benefits | S14: LTC
C15: Other Asset | F15: 529 | O15: Identity | S15: Other
F16: UTMA / UGMA | O16: Other
F17: Business
F18: Other

Sheet 00 README
A1: CFP Client Planning Data Workbook
A2: Use this workbook as a secure planning intake and ongoing update file. Yellow cells are inputs; green cells are formulas or calculated outputs.
A4: Topic | B4: Guidance
A5: Purpose | B5: This workbook captures the client data a CFP professional typically needs to guide household financial planning: profile, goals, cash flow, assets, liabilities, insurance, taxes, retirement, benefits, estate, beneficiaries, documents, and action items.
A6: How to use | B6: Start with Client Profile, Assumptions, Documents, Assets, Liabilities, and Cash Flow. Mark rows Active when they should be included in dashboard totals.
A7: Privacy | B7: Avoid storing full Social Security numbers or full account numbers. Use last four digits only. Store the file securely and do not transmit it through unsecured channels.
A8: Review cadence | B8: Update values before each planning meeting, major life event, job change, tax filing, estate update, refinance, or insurance renewal.
A9: Advisor workflow | B9: Use the Data Map and Documents tabs as intake checklists. Use the Action Plan tab for recommendations, owner, due date, and follow-up status.
A10: Customization | B10: The Lists tab powers dropdowns. Customize categories to match your planning process, CRM, or financial planning software.

Sheet Retirement Projection
A1: Year | B1: Age | C1: Beginning | D1: Growth | E1: Social Security | F1: Annual Expenses | G1: Gross Withdrawal | H1: MAGI | I1: 0%cap gain | J1: Real AGI | K1: Taxes (Fec/CA) | L1: Ending Balance | M1: Use of Cost basis | N1: Cap G 0% | O1: Cap G 15% | P1: HSA Contribution | Q1: MAGI CC limit | R1: Mortgage | S1: Home Value | U1: Networth | Y1: MAGI only allows the deduction of, HSA, Student Loans, Capital Gains Losses. No Standard deduction or itemized count
A2: 2027 | B2: ='03 Client Profile'!$D$5 + (A2 - YEAR('02 Assumptions'!$B$16)) -> 37 | C2: ='01 Dashboard'!$E$6 + '01 Dashboard'!$E$9 + '01 Dashboard'!$E$10 -> 2912398 | D2: =C2 * $Z$43 -> 145619.9 | E2: =IF(B2>=67, '18 Social Security'!$G$5 * (1 + '02 Assumptions'!$B$5)^(B2 - '03 Client Profile'!$D$5), 0) -> 0 | F2: {=MAP(A2:A50540, LAMBDA(y, IF(y="",, SUMIFS('05 Cash Flow'!G:G, '05 Cash Flow'!A:A, "Expense") * (1 + '02 Assumptions'!B5)^(y - 2026))))} -> 169380.67 | G2: =F2 -> 169380.67 | H2: =G2-P2-M2 -> 158884.01 | I2: =H2-N2 -> 108394.01 | J2: =H2-N2-AB48-AE47 -> 72515.286 | K2: =J2 * 0.15 + SUMPRODUCT(--(J2 > {0, 11079, 26264, 41452, 57542, 72724, 371479, 445771, 742953}), (J2 - {0, 11079, 26264, 41452, 57542, 72724, 371479, 445771, 742953}), {0.01, 0.01, 0.02, 0.02, 0.02, 0.013, 0.01, 0.01, 0.01}) -> 14062.566 | L2: =C2 + D2 - G2-K2 -> 2874574.7 | M2: =AD42 -> 5996.6632 | N2: =49500 * (1 + $Z$47)^($A2-2026) -> 50490 | O2: 0 | P2: =4500*(1+$Z$47)^(A2-2027)+IF(B2>=55,1000,0) -> 4500 | Q2: =62600*(1+$Z$47)^(A2-2026) -> 63852 | R2: =PV($AD$50 / 12, 12*$AE$50, -$AF$50) -> 372138.39 | S2: 1000000 | U2: =S2+L2-R2 -> 3502436.3 | Y2: AGI counts itemized and standard deductions.
A3: =A2+1 -> 2028 | B3: =B2+1 -> 38 | C3: =L2 -> 2874574.7 | D3: =C3 * $Z$43 -> 143728.73 | E3: =IF(B3>=67, '18 Social Security'!$G$5 * (1 + '02 Assumptions'!$B$5)^(B3 - '03 Client Profile'!$D$5), 0) -> 0 | F3: 172768.28 | G3: =F3 -> 172768.28 | H3: =G3-P3-M3 -> 162181.62 | I3: =H3-49450-$AD$42-$AE$47-$AB$48 -> 70856.237 | J3: =I3-M3 -> 64859.573 | K3: =J3 * 0.15 + SUMPRODUCT(--(J3 > {0, 11079, 26264, 41452, 57542, 72724, 371479, 445771, 742953}), (J3 - {0, 11079, 26264, 41452, 57542, 72724, 371479, 445771, 742953}), {0.01, 0.01, 0.02, 0.02, 0.02, 0.013, 0.01, 0.01, 0.01}) -> 12301.752 | L3: =C3 + D3 - G3-K3 -> 2833233.4 | M3: =M2 -> 5996.6632 | N3: =49500 * (1 + $Z$47)^($A3-2026) -> 51499.8 | O3: 0 | P3: =4500*(1+$Z$47)^(A3-2027)+IF(B3>=55,1000,0) -> 4590 | Q3: =62600*(1+$Z$47)^(A3-2026) -> 65129.04 | R3: =PV($AD$50 / 12, 12*($AE$50-ROW(R1)), -$AF$50) -> 367002.39 | S3: =S2*1.03 -> 1030000 | U3: =S3+L3-R3 -> 3496231
A4: =A3+1 -> 2029 | B4: =B3+1 -> 39 | C4: =L3 -> 2833233.4 | D4: =C4 * $Z$43 -> 141661.67 | E4: =IF(B4>=67, '18 Social Security'!$G$5 * (1 + '02 Assumptions'!$B$5)^(B4 - '03 Client Profile'!$D$5), 0) -> 0 | F4: 176223.65 | G4: =F4 -> 176223.65 | H4: =G4-P4-M4 -> 165545.19 | I4: =H4-49450-$AD$42-$AE$47-$AB$48 -> 74219.802 | J4: =I4-M4 -> 68223.139 | K4: =J4 * 0.15 + SUMPRODUCT(--(J4 > {0, 11079, 26264, 41452, 57542, 72724, 371479, 445771, 742953}), (J4 - {0, 11079, 26264, 41452, 57542, 72724, 371479, 445771, 742953}), {0.01, 0.01, 0.02, 0.02, 0.02, 0.013, 0.01, 0.01, 0.01}) -> 13075.372 | L4: =C4 + D4 - G4-K4 -> 2785596 | M4: =M3 -> 5996.6632 | N4: =49500 * (1 + $Z$47)^($A4-2026) -> 52529.796 | O4: 0 | P4: =4500*(1+$Z$47)^(A4-2027)+IF(B4>=55,1000,0) -> 4681.8 | Q4: =62600*(1+$Z$47)^(A4-2026) -> 66431.621 | R4: =PV($AD$50 / 12, 12*($AE$50-ROW(R2)), -$AF$50) -> 361563.17 | S4: =S3*1.03 -> 1060900 | U4: =S4+L4-R4 -> 3484932.8
A5: =A4+1 -> 2030 | B5: =B4+1 -> 40 | C5: =L4 -> 2785596 | D5: =C5 * $Z$43 -> 139279.8 | E5: =IF(B5>=67, '18 Social Security'!$G$5 * (1 + '02 Assumptions'!$B$5)^(B5 - '03 Client Profile'!$D$5), 0) -> 0 | F5: 179748.12 | G5: =F5 -> 179748.12 | H5: =G5-P5-M5 -> 168976.02 | I5: =H5-49450-$AD$42-$AE$47-$AB$48 -> 77650.639 | J5: =I5-M5 -> 71653.976 | K5: =J5 * 0.15 + SUMPRODUCT(--(J5 > {0, 11079, 26264, 41452, 57542, 72724, 371479, 445771, 742953}), (J5 - {0, 11079, 26264, 41452, 57542, 72724, 371479, 445771, 742953}), {0.01, 0.01, 0.02, 0.02, 0.02, 0.013, 0.01, 0.01, 0.01}) -> 13864.464 | L5: =C5 + D5 - G5-K5 -> 2731263.2 | M5: =M4 -> 5996.6632 | N5: =49500 * (1 + $Z$47)^($A5-2026) -> 53580.392 | O5: 0 | P5: =4500*(1+$Z$47)^(A5-2027)+IF(B5>=55,1000,0) -> 4775.436 | Q5: =62600*(1+$Z$47)^(A5-2026) -> 67760.253 | R5: =PV($AD$50 / 12, 12*($AE$50-ROW(R3)), -$AF$50) -> 355802.82 | S5: =S4*1.03 -> 1092727 | U5: =S5+L5-R5 -> 3468187.4
A6: =A5+1 -> 2031 | B6: =B5+1 -> 41 | C6: =L5 -> 2731263.2 | D6: =C6 * $Z$43 -> 136563.16 | E6: =IF(B6>=67, '18 Social Security'!$G$5 * (1 + '02 Assumptions'!$B$5)^(B6 - '03 Client Profile'!$D$5), 0) -> 0 | F6: 183343.08 | G6: =F6 -> 183343.08 | H6: =G6-P6-M6 -> 172475.48 | I6: =H6-49450-$AD$42-$AE$47-$AB$48 -> 81150.093 | J6: =I6-M6 -> 75153.43 | K6: =J6 * 0.15 + SUMPRODUCT(--(J6 > {0, 11079, 26264, 41452, 57542, 72724, 371479, 445771, 742953}), (J6 - {0, 11079, 26264, 41452, 57542, 72724, 371479, 445771, 742953}), {0.01, 0.01, 0.02, 0.02, 0.02, 0.013, 0.01, 0.01, 0.01}) -> 14700.921 | L6: =C6 + D6 - G6-K6 -> 2669782.4 | M6: =M5 -> 5996.6632 | N6: =49500 * (1 + $Z$47)^($A6-2026) -> 54652 | O6: 0 | P6: =4500*(1+$Z$47)^(A6-2027)+IF(B6>=55,1000,0) -> 4870.9447 | Q6: =62600*(1+$Z$47)^(A6-2026) -> 69115.458 | R6: =PV($AD$50 / 12, 12*($AE$50-ROW(R4)), -$AF$50) -> 349702.37 | S6: =S5*1.03 -> 1125508.8 | U6: =S6+L6-R6 -> 3445588.8
A7: =A6+1 -> 2032 | B7: =B6+1 -> 42 | C7: =L6 -> 2669782.4 | D7: =C7 * $Z$43 -> 133489.12 | E7: =IF(B7>=67, '18 Social Security'!$G$5 * (1 + '02 Assumptions'!$B$5)^(B7 - '03 Client Profile'!$D$5), 0) -> 0 | F7: 187009.95 | G7: =F7 -> 187009.95 | H7: =G7-P7-M7 -> 176044.92 | I7: =H7-49450-$AD$42-$AE$47-$AB$48 -> 84719.536 | J7: =I7-M7 -> 78722.872 | K7: =J7 * 0.15 + SUMPRODUCT(--(J7 > {0, 11079, 26264, 41452, 57542, 72724, 371479, 445771, 742953}), (J7 - {0, 11079, 26264, 41452, 57542, 72724, 371479, 445771, 742953}), {0.01, 0.01, 0.02, 0.02, 0.02, 0.013, 0.01, 0.01, 0.01}) -> 15568.296 | L7: =C7 + D7 - G7-K7 -> 2600693.2 | M7: =M6 -> 5996.6632 | N7: =49500 * (1 + $Z$47)^($A7-2026) -> 55745.04 | O7: 0 | P7: =4500*(1+$Z$47)^(A7-2027)+IF(B7>=55,1000,0) -> 4968.3636 | Q7: =62600*(1+$Z$47)^(A7-2026) -> 70497.767 | R7: =PV($AD$50 / 12, 12*($AE$50-ROW(R5)), -$AF$50) -> 343241.76 | S7: =S6*1.03 -> 1159274.1 | U7: =S7+L7-R7 -> 3416725.6
A8: =A7+1 -> 2033 | B8: =B7+1 -> 43 | C8: =L7 -> 2600693.2 | D8: =C8 * $Z$43 -> 130034.66 | E8: =IF(B8>=67, '18 Social Security'!$G$5 * (1 + '02 Assumptions'!$B$5)^(B8 - '03 Client Profile'!$D$5), 0) -> 0 | F8: 190750.14 | G8: =F8 -> 190750.14 | H8: =G8-P8-M8 -> 179685.75 | I8: =H8-49450-$AD$42-$AE$47-$AB$48 -> 88360.367 | J8: =I8-M8 -> 82363.704 | K8: =J8 * 0.15 + SUMPRODUCT(--(J8 > {0, 11079, 26264, 41452, 57542, 72724, 371479, 445771, 742953}), (J8 - {0, 11079, 26264, 41452, 57542, 72724, 371479, 445771, 742953}), {0.01, 0.01, 0.02, 0.02, 0.02, 0.013, 0.01, 0.01, 0.01}) -> 16453.018 | L8: =C8 + D8 - G8-K8 -> 2523524.7 | M8: =M7 -> 5996.6632 | N8: =49500 * (1 + $Z$47)^($A8-2026) -> 56859.941 | O8: 0 | P8: =4500*(1+$Z$47)^(A8-2027)+IF(B8>=55,1000,0) -> 5067.7309 | Q8: =62600*(1+$Z$47)^(A8-2026) -> 71907.723 | R8: =PV($AD$50 / 12, 12*($AE$50-ROW(R6)), -$AF$50) -> 336399.71 | S8: =S7*1.03 -> 1194052.3 | U8: =S8+L8-R8 -> 3381177.3
A9: =A8+1 -> 2034 | B9: =B8+1 -> 44 | C9: =L8 -> 2523524.7 | D9: =C9 * $Z$43 -> 126176.24 | E9: =IF(B9>=67, '18 Social Security'!$G$5 * (1 + '02 Assumptions'!$B$5)^(B9 - '03 Client Profile'!$D$5), 0) -> 0 | F9: 194565.15 | G9: =F9 -> 194565.15 | H9: =G9-P9-M9 -> 183399.4 | I9: =H9-49450-$AD$42-$AE$47-$AB$48 -> 92074.016 | J9: =I9-M9 -> 86077.352 | K9: =J9 * 0.15 + SUMPRODUCT(--(J9 > {0, 11079, 26264, 41452, 57542, 72724, 371479, 445771, 742953}), (J9 - {0, 11079, 26264, 41452, 57542, 72724, 371479, 445771, 742953}), {0.01, 0.01, 0.02, 0.02, 0.02, 0.013, 0.01, 0.01, 0.01}) -> 17355.435 | L9: =C9 + D9 - G9-K9 -> 2437780.4 | M9: =M8 -> 5996.6632 | N9: =49500 * (1 + $Z$47)^($A9-2026) -> 57997.139 | O9: 0 | P9: =4500*(1+$Z$47)^(A9-2027)+IF(B9>=55,1000,0) -> 5169.0855 | Q9: =62600*(1+$Z$47)^(A9-2026) -> 73345.877 | R9: =PV($AD$50 / 12, 12*($AE$50-ROW(R7)), -$AF$50) -> 329153.71 | S9: =S8*1.03 -> 1229873.9 | U9: =S9+L9-R9 -> 3338500.6
A10: =A9+1 -> 2035 | B10: =B9+1 -> 45 | C10: =L9 -> 2437780.4 | D10: =C10 * $Z$43 -> 121889.02 | E10: =IF(B10>=67, '18 Social Security'!$G$5 * (1 + '02 Assumptions'!$B$5)^(B10 - '03 Client Profile'!$D$5), 0) -> 0 | F10: 198456.45 | G10: =F10 -> 198456.45 | H10: =G10-P10-M10 -> 187187.32 | I10: =H10-49450-$AD$42-$AE$47-$AB$48 -> 95861.937 | J10: =I10-M10 -> 89865.274 | K10: =J10 * 0.15 + SUMPRODUCT(--(J10 > {0, 11079, 26264, 41452, 57542, 72724, 371479, 445771, 742953}), (J10 - {0, 11079, 26264, 41452, 57542, 72724, 371479, 445771, 742953}), {0.01, 0.01, 0.02, 0.02, 0.02, 0.013, 0.01, 0.01, 0.01}) -> 18275.899 | L10: =C10 + D10 - G10-K10 -> 2342937.1 | M10: =M9 -> 5996.6632 | N10: =49500 * (1 + $Z$47)^($A10-2026) -> 59157.082 | O10: 0 | P10: =4500*(1+$Z$47)^(A10-2027)+IF(B10>=55,1000,0) -> 5272.4672 | Q10: =62600*(1+$Z$47)^(A10-2026) -> 74812.795 | R10: =PV($AD$50 / 12, 12*($AE$50-ROW(R8)), -$AF$50) -> 321479.9 | S10: =S9*1.03 -> 1266770.1 | U10: =S10+L10-R10 -> 3288227.2
A11: =A10+1 -> 2036 | B11: =B10+1 -> 46 | C11: =L10 -> 2342937.1 | D11: =C11 * $Z$43 -> 117146.85 | E11: =IF(B11>=67, '18 Social Security'!$G$5 * (1 + '02 Assumptions'!$B$5)^(B11 - '03 Client Profile'!$D$5), 0) -> 0 | F11: 202425.58 | G11: =F11 -> 202425.58 | H11: =G11-P11-M11 -> 191051 | I11: =H11-49450-$AD$42-$AE$47-$AB$48 -> 99725.617 | J11: =I11-M11 -> 93728.953 | K11: =J11 * 0.15 + SUMPRODUCT(--(J11 > {0, 11079, 26264, 41452, 57542, 72724, 371479, 445771, 742953}), (J11 - {0, 11079, 26264, 41452, 57542, 72724, 371479, 445771, 742953}), {0.01, 0.01, 0.02, 0.02, 0.02, 0.013, 0.01, 0.01, 0.01}) -> 19214.774 | L11: =C11 + D11 - G11-K11 -> 2238443.6 | M11: =M10 -> 5996.6632 | N11: =49500 * (1 + $Z$47)^($A11-2026) -> 60340.224 | O11: 0 | P11: =4500*(1+$Z$47)^(A11-2027)+IF(B11>=55,1000,0) -> 5377.9166 | Q11: =62600*(1+$Z$47)^(A11-2026) -> 76309.051 | R11: =PV($AD$50 / 12, 12*($AE$50-ROW(R9)), -$AF$50) -> 313353.04 | S11: =S10*1.03 -> 1304773.2 | U11: =S11+L11-R11 -> 3229863.7
A12: =A11+1 -> 2037 | B12: =B11+1 -> 47 | C12: =L11 -> 2238443.6 | D12: =C12 * $Z$43 -> 111922.18 | E12: =IF(B12>=67, '18 Social Security'!$G$5 * (1 + '02 Assumptions'!$B$5)^(B12 - '03 Client Profile'!$D$5), 0) -> 0 | F12: 206474.09 | G12: =F12 -> 206474.09 | H12: =G12-P12-M12 -> 194991.95 | I12: =H12-49450-$AD$42-$AE$47-$AB$48 -> 103666.57 | J12: =I12-M12 -> 97669.907 | K12: =J12 * 0.15 + SUMPRODUCT(--(J12 > {0, 11079, 26264, 41452, 57542, 72724, 371479, 445771, 742953}), (J12 - {0, 11079, 26264, 41452, 57542, 72724, 371479, 445771, 742953}), {0.01, 0.01, 0.02, 0.02, 0.02, 0.013, 0.01, 0.01, 0.01}) -> 20172.425 | L12: =C12 + D12 - G12-K12 -> 2123719.2 | M12: =M11 -> 5996.6632 | N12: =49500 * (1 + $Z$47)^($A12-2026) -> 61547.028 | O12: 0 | P12: =4500*(1+$Z$47)^(A12-2027)+IF(B12>=55,1000,0) -> 5485.4749 | Q12: =62600*(1+$Z$47)^(A12-2026) -> 77835.232 | R12: =PV($AD$50 / 12, 12*($AE$50-ROW(R10)), -$AF$50) -> 304746.36 | S12: =S11*1.03 -> 1343916.4 | U12: =S12+L12-R12 -> 3162889.2
A13: =A12+1 -> 2038 | B13: =B12+1 -> 48 | C13: =L12 -> 2123719.2 | D13: =C13 * $Z$43 -> 106185.96 | E13: =IF(B13>=67, '18 Social Security'!$G$5 * (1 + '02 Assumptions'!$B$5)^(B13 - '03 Client Profile'!$D$5), 0) -> 0 | F13: 210603.57 | G13: =F13 -> 210603.57 | H13: =G13-P13-M13 -> 199011.73 | I13: =H13-49450-$AD$42-$AE$47-$AB$48 -> 107686.34 | J13: =I13-M13 -> 101689.68 | K13: =J13 * 0.15 + SUMPRODUCT(--(J13 > {0, 11079, 26264, 41452, 57542, 72724, 371479, 445771, 742953}), (J13 - {0, 11079, 26264, 41452, 57542, 72724, 371479, 445771, 742953}), {0.01, 0.01, 0.02, 0.02, 0.02, 0.013, 0.01, 0.01, 0.01}) -> 21149.23 | L13: =C13 + D13 - G13-K13 -> 1998152.4 | M13: =M12 -> 5996.6632 | N13: =49500 * (1 + $Z$47)^($A13-2026) -> 62777.969 | O13: 0 | P13: =4500*(1+$Z$47)^(A13-2027)+IF(B13>=55,1000,0) -> 5595.1844 | Q13: =62600*(1+$Z$47)^(A13-2026) -> 79391.936 | R13: =PV($AD$50 / 12, 12*($AE$50-ROW(R11)), -$AF$50) -> 295631.56 | S13: =S12*1.03 -> 1384233.9 | U13: =S13+L13-R13 -> 3086754.7
A14: =A13+1 -> 2039 | B14: =B13+1 -> 49 | C14: =L13 -> 1998152.4 | D14: =C14 * $Z$43 -> 99907.619 | E14: =IF(B14>=67, '18 Social Security'!$G$5 * (1 + '02 Assumptions'!$B$5)^(B14 - '03 Client Profile'!$D$5), 0) -> 0 | F14: 214815.64 | G14: =F14 -> 214815.64 | H14: =G14-P14-M14 -> 203111.89 | I14: =H14-49450-$AD$42-$AE$47-$AB$48 -> 111786.51 | J14: =I14-M14 -> 105789.85 | K14: =J14 * 0.15 + SUMPRODUCT(--(J14 > {0, 11079, 26264, 41452, 57542, 72724, 371479, 445771, 742953}), (J14 - {0, 11079, 26264, 41452, 57542, 72724, 371479, 445771, 742953}), {0.01, 0.01, 0.02, 0.02, 0.02, 0.013, 0.01, 0.01, 0.01}) -> 22145.571 | L14: =C14 + D14 - G14-K14 -> 1861098.8 | M14: =M13 -> 5996.6632 | N14: =49500 * (1 + $Z$47)^($A14-2026) -> 64033.528 | O14: 0 | P14: =4500*(1+$Z$47)^(A14-2027)+IF(B14>=55,1000,0) -> 5707.0881 | Q14: =62600*(1+$Z$47)^(A14-2026) -> 80979.775 | R14: =PV($AD$50 / 12, 12*($AE$50-ROW(R12)), -$AF$50) -> 285978.61 | S14: =S13*1.03 -> 1425760.9 | U14: =S14+L14-R14 -> 3000881.1
... A24: =A23+1 -> 2049 | B24: =B23+1 -> 59 | C24: =L23 -> -12972.063 | D24: =C24 * $Z$43 -> -648.60314 | E24: =IF(B24>=67, '18 Social Security'!$G$5 * (1 + '02 Assumptions'!$B$5)^(B24 - '03 Client Profile'!$D$5), 0) -> 0 | F24: 261859.07 | G24: =F24 -> 261859.07 | H24: =G24-P24-M24 -> 247905.5 | I24: =H24-49450-$AD$42-$AE$47-$AB$48 -> 156580.12 | J24: =I24-M24 -> 150583.45 | K24: =J24 * 0.15 + SUMPRODUCT(--(J24 > {0, 11079, 26264, 41452, 57542, 72724, 371479, 445771, 742953}), (J24 - {0, 11079, 26264, 41452, 57542, 72724, 371479, 445771, 742953}), {0.01, 0.01, 0.02, 0.02, 0.02, 0.013, 0.01, 0.01, 0.01}) -> 33030.417 | L24: =C24 + D24 - G24-K24 -> -308510.16 | M24: =M23 -> 5996.6632 | N24: =49500 * (1 + $Z$47)^($A24-2026) -> 78056.514 | O24: 0 | P24: =4500*(1+$Z$47)^(A24-2027)+IF(B24>=55,1000,0) -> 7956.9085 | Q24: =62600*(1+$Z$47)^(A24-2026) -> 98713.894 | R24: =PV($AD$50 / 12, 12*($AE$50-ROW(R22)), -$AF$50) -> 151839.31 | S24: =S23*1.03 -> 1916103.4 | U24: =S24+L24-R24 -> 1455753.9
A25: =A24+1 -> 2050 | B25: =B24+1 -> 60 | C25: =L24 -> -308510.16 | D25: =C25 * $Z$43 -> -15425.508 | E25: =IF(B25>=67, '18 Social Security'!$G$5 * (1 + '02 Assumptions'!$B$5)^(B25 - '03 Client Profile'!$D$5), 0) -> 0 | F25: 267096.25 | G25: =F25 -> 267096.25 | H25: =G25-P25-M25 -> 253003.54 | I25: =H25-49450-$AD$42-$AE$47-$AB$48 -> 161678.16 | J25: =I25-M25 -> 155681.5 | K25: =J25 * 0.15 + SUMPRODUCT(--(J25 > {0, 11079, 26264, 41452, 57542, 72724, 371479, 445771, 742953}), (J25 - {0, 11079, 26264, 41452, 57542, 72724, 371479, 445771, 742953}), {0.01, 0.01, 0.02, 0.02, 0.02, 0.013, 0.01, 0.01, 0.01}) -> 34269.242 | L25: =C25 + D25 - G25-K25 -> -625301.16 | M25: =M24 -> 5996.6632 | N25: =49500 * (1 + $Z$47)^($A25-2026) -> 79617.644 | O25: 0 | P25: =4500*(1+$Z$47)^(A25-2027)+IF(B25>=55,1000,0) -> 8096.0467 | Q25: =62600*(1+$Z$47)^(A25-2026) -> 100688.17 | R25: =PV($AD$50 / 12, 12*($AE$50-ROW(R23)), -$AF$50) -> 133696.89 | S25: =S24*1.03 -> 1973586.5 | U25: =S25+L25-R25 -> 1214588.5 | AG25: 185000 | AH25: 15000
A26: =A25+1 -> 2051 | B26: =B25+1 -> 61 | C26: =L25 -> -625301.16 | D26: =C26 * $Z$43 -> -31265.058 | E26: =IF(B26>=67, '18 Social Security'!$G$5 * (1 + '02 Assumptions'!$B$5)^(B26 - '03 Client Profile'!$D$5), 0) -> 0 | F26: 272438.18 | G26: =F26 -> 272438.18 | H26: =G26-P26-M26 -> 258203.55 | I26: =H26-49450-$AD$42-$AE$47-$AB$48 -> 166878.16 | J26: =I26-M26 -> 160881.5 | K26: =J26 * 0.15 + SUMPRODUCT(--(J26 > {0, 11079, 26264, 41452, 57542, 72724, 371479, 445771, 742953}), (J26 - {0, 11079, 26264, 41452, 57542, 72724, 371479, 445771, 742953}), {0.01, 0.01, 0.02, 0.02, 0.02, 0.013, 0.01, 0.01, 0.01}) -> 35532.843 | L26: =C26 + D26 - G26-K26 -> -964537.24 | M26: =M25 -> 5996.6632 | N26: =49500 * (1 + $Z$47)^($A26-2026) -> 81209.997 | O26: 0 | P26: =4500*(1+$Z$47)^(A26-2027)+IF(B26>=55,1000,0) -> 8237.9676 | Q26: =62600*(1+$Z$47)^(A26-2026) -> 102701.94 | R26: =PV($AD$50 / 12, 12*($AE$50-ROW(R24)), -$AF$50) -> 114483.35 | S26: =S25*1.03 -> 2032794.1 | U26: =S26+L26-R26 -> 953773.52 | AH26: 160000
A27: =A26+1 -> 2052 | B27: =B26+1 -> 62 | C27: =L26 -> -964537.24 | D27: =C27 * $Z$43 -> -48226.862 | E27: =IF(B27>=67, '18 Social Security'!$G$5 * (1 + '02 Assumptions'!$B$5)^(B27 - '03 Client Profile'!$D$5), 0) -> 0 | F27: 277886.94 | G27: =F27 -> 277886.94 | H27: =G27-P27-M27 -> 263507.55 | I27: =H27-49450-$AD$42-$AE$47-$AB$48 -> 172182.17 | J27: =I27-M27 -> 166185.51 | K27: =J27 * 0.15 + SUMPRODUCT(--(J27 > {0, 11079, 26264, 41452, 57542, 72724, 371479, 445771, 742953}), (J27 - {0, 11079, 26264, 41452, 57542, 72724, 371479, 445771, 742953}), {0.01, 0.01, 0.02, 0.02, 0.02, 0.013, 0.01, 0.01, 0.01}) -> 36821.716 | L27: =C27 + D27 - G27-K27 -> -1327472.8 | M27: =M26 -> 5996.6632 | N27: =49500 * (1 + $Z$47)^($A27-2026) -> 82834.197 | O27: 0 | P27: =4500*(1+$Z$47)^(A27-2027)+IF(B27>=55,1000,0) -> 8382.727 | Q27: =62600*(1+$Z$47)^(A27-2026) -> 104755.97 | R27: =PV($AD$50 / 12, 12*($AE$50-ROW(R25)), -$AF$50) -> 94135.444 | S27: =S26*1.03 -> 2093777.9 | U27: =S27+L27-R27 -> 672169.73
A28: =A27+1 -> 2053 | B28: =B27+1 -> 63 | C28: =L27 -> -1327472.8 | D28: =C28 * $Z$43 -> -66373.638 | E28: =IF(B28>=67, '18 Social Security'!$G$5 * (1 + '02 Assumptions'!$B$5)^(B28 - '03 Client Profile'!$D$5), 0) -> 0 | F28: 283444.68 | G28: =F28 -> 283444.68 | H28: =G28-P28-M28 -> 268917.64 | I28: =H28-49450-$AD$42-$AE$47-$AB$48 -> 177592.25 | J28: =I28-M28 -> 171595.59 | K28: =J28 * 0.15 + SUMPRODUCT(--(J28 > {0, 11079, 26264, 41452, 57542, 72724, 371479, 445771, 742953}), (J28 - {0, 11079, 26264, 41452, 57542, 72724, 371479, 445771, 742953}), {0.01, 0.01, 0.02, 0.02, 0.02, 0.013, 0.01, 0.01, 0.01}) -> 38136.366 | L28: =C28 + D28 - G28-K28 -> -1715427.4 | M28: =M27 -> 5996.6632 | N28: =49500 * (1 + $Z$47)^($A28-2026) -> 84490.881 | O28: 0 | P28: =4500*(1+$Z$47)^(A28-2027)+IF(B28>=55,1000,0) -> 8530.3815 | Q28: =62600*(1+$Z$47)^(A28-2026) -> 106851.09 | R28: =PV($AD$50 / 12, 12*($AE$50-ROW(R26)), -$AF$50) -> 72586.202 | S28: =S27*1.03 -> 2156591.3 | U28: =S28+L28-R28 -> 368577.62
A29: =A28+1 -> 2054 | B29: =B28+1 -> 64 | C29: =L28 -> -1715427.4 | D29: =C29 * $Z$43 -> -85771.372 | E29: =IF(B29>=67, '18 Social Security'!$G$5 * (1 + '02 Assumptions'!$B$5)^(B29 - '03 Client Profile'!$D$5), 0) -> 0 | F29: 289113.57 | G29: =F29 -> 289113.57 | H29: =G29-P29-M29 -> 274435.92 | I29: =H29-49450-$AD$42-$AE$47-$AB$48 -> 183110.54 | J29: =I29-M29 -> 177113.88 | K29: =J29 * 0.15 + SUMPRODUCT(--(J29 > {0, 11079, 26264, 41452, 57542, 72724, 371479, 445771, 742953}), (J29 - {0, 11079, 26264, 41452, 57542, 72724, 371479, 445771, 742953}), {0.01, 0.01, 0.02, 0.02, 0.02, 0.013, 0.01, 0.01, 0.01}) -> 39477.31 | L29: =C29 + D29 - G29-K29 -> -2129789.7 | M29: =M28 -> 5996.6632 | N29: =49500 * (1 + $Z$47)^($A29-2026) -> 86180.698 | O29: 0 | P29: =4500*(1+$Z$47)^(A29-2027)+IF(B29>=55,1000,0) -> 8680.9891 | Q29: =62600*(1+$Z$47)^(A29-2026) -> 108988.12 | R29: =PV($AD$50 / 12, 12*($AE$50-ROW(R27)), -$AF$50) -> 49764.695 | S29: =S28*1.03 -> 2221289 | U29: =S29+L29-R29 -> 41734.613
A30: =A29+1 -> 2055 | B30: =B29+1 -> 65 | C30: =L29 -> -2129789.7 | D30: =C30 * $Z$43 -> -106489.48 | E30: =IF(B30>=67, '18 Social Security'!$G$5 * (1 + '02 Assumptions'!$B$5)^(B30 - '03 Client Profile'!$D$5), 0) -> 0 | F30: 294895.85 | G30: =F30 -> 294895.85 | H30: =G30-P30-M30 -> 280064.57 | I30: =H30-49450-$AD$42-$AE$47-$AB$48 -> 188739.19 | J30: =I30-M30 -> 182742.53 | K30: =J30 * 0.15 + SUMPRODUCT(--(J30 > {0, 11079, 26264, 41452, 57542, 72724, 371479, 445771, 742953}), (J30 - {0, 11079, 26264, 41452, 57542, 72724, 371479, 445771, 742953}), {0.01, 0.01, 0.02, 0.02, 0.02, 0.013, 0.01, 0.01, 0.01}) -> 40845.072 | L30: =C30 + D30 - G30-K30 -> -2572020.1 | M30: =M29 -> 5996.6632 | N30: =49500 * (1 + $Z$47)^($A30-2026) -> 87904.312 | O30: 0 | P30: =4500*(1+$Z$47)^(A30-2027)+IF(B30>=55,1000,0) -> 8834.6089 | Q30: =62600*(1+$Z$47)^(A30-2026) -> 111167.88 | R30: =PV($AD$50 / 12, 12*($AE$50-ROW(R28)), -$AF$50) -> 25595.811 | S30: =S29*1.03 -> 2287927.7 | U30: =S30+L30-R30 -> -309688.24
A31: =A30+1 -> 2056 | B31: =B30+1 -> 66 | C31: =L30 -> -2572020.1 | D31: =C31 * $Z$43 -> -128601.01 | E31: =IF(B31>=67, '18 Social Security'!$G$5 * (1 + '02 Assumptions'!$B$5)^(B31 - '03 Client Profile'!$D$5), 0) -> 0 | F31: 300793.76 | G31: =F31 -> 300793.76 | H31: =G31-P31-M31 -> 285805.8 | I31: =H31-49450-$AD$42-$AE$47-$AB$48 -> 194480.42 | J31: =I31-M31 -> 188483.75 | K31: =J31 * 0.15 + SUMPRODUCT(--(J31 > {0, 11079, 26264, 41452, 57542, 72724, 371479, 445771, 742953}), (J31 - {0, 11079, 26264, 41452, 57542, 72724, 371479, 445771, 742953}), {0.01, 0.01, 0.02, 0.02, 0.02, 0.013, 0.01, 0.01, 0.01}) -> 42240.19 | L31: =C31 + D31 - G31-K31 -> -3043655.1 | M31: =M30 -> 5996.6632 | N31: =49500 * (1 + $Z$47)^($A31-2026) -> 89662.398 | O31: 0 | P31: =4500*(1+$Z$47)^(A31-2027)+IF(B31>=55,1000,0) -> 8991.3011 | Q31: =62600*(1+$Z$47)^(A31-2026) -> 113391.24 | R31: =PV($AD$50 / 12, 12*($AE$50-ROW(R29)), -$AF$50) -> 0 | S31: =S30*1.03 -> 2356565.5 | U31: =S31+L31-R31 -> -687089.55
A32: =A31+1 -> 2057 | B32: =B31+1 -> 67 | C32: =L31 -> -3043655.1 | D32: =C32 * $Z$43 -> -152182.75 | E32: =IF(B32>=67, '18 Social Security'!$G$5 * (1 + '02 Assumptions'!$B$5)^(B32 - '03 Client Profile'!$D$5), 0) -> 66513.197 | F32: 306809.64 | G32: =F32-E32 -> 240296.44 | H32: =G32-P32-M32 -> 225148.65 | I32: =H32-49450-$AD$42-$AE$47-$AB$48 -> 133823.27 | J32: =I32-M32 -> 127826.6 | K32: =J32 * 0.15 + SUMPRODUCT(--(J32 > {0, 11079, 26264, 41452, 57542, 72724, 371479, 445771, 742953}), (J32 - {0, 11079, 26264, 41452, 57542, 72724, 371479, 445771, 742953}), {0.01, 0.01, 0.02, 0.02, 0.02, 0.013, 0.01, 0.01, 0.01}) -> 27500.503 | L32: =C32 + D32 - G32-K32 -> -3463634.8 | M32: =M31 -> 5996.6632 | N32: =49500 * (1 + $Z$47)^($A32-2026) -> 91455.646 | O32: 0 | P32: =4500*(1+$Z$47)^(A32-2027)+IF(B32>=55,1000,0) -> 9151.1271 | Q32: =62600*(1+$Z$47)^(A32-2026) -> 115659.06 | S32: =S31*1.03 -> 2427262.5 | U32: =S32+L32-R32 -> -1036372.3
A33: =A32+1 -> 2058 | B33: =B32+1 -> 68 | C33: =L32 -> -3463634.8 | D33: =C33 * $Z$43 -> -173181.74 | E33: =IF(B33>=67, '18 Social Security'!$G$5 * (1 + '02 Assumptions'!$B$5)^(B33 - '03 Client Profile'!$D$5), 0) -> 67843.461 | F33: 312945.83 | G33: =F33-E33 -> 245102.37 | H33: =G33-P33-M33 -> 229791.56 | I33: =H33-49450-$AD$42-$AE$47-$AB$48 -> 138466.17 | J33: =I33-M33 -> 132469.51 | K33: =J33 * 0.15 + SUMPRODUCT(--(J33 > {0, 11079, 26264, 41452, 57542, 72724, 371479, 445771, 742953}), (J33 - {0, 11079, 26264, 41452, 57542, 72724, 371479, 445771, 742953}), {0.01, 0.01, 0.02, 0.02, 0.02, 0.013, 0.01, 0.01, 0.01}) -> 28628.729 | L33: =C33 + D33 - G33-K33 -> -3910547.6 | M33: =M32 -> 5996.6632 | N33: =49500 * (1 + $Z$47)^($A33-2026) -> 93284.759 | O33: 0 | P33: =4500*(1+$Z$47)^(A33-2027)+IF(B33>=55,1000,0) -> 9314.1497 | Q33: =62600*(1+$Z$47)^(A33-2026) -> 117972.24 | S33: =S32*1.03 -> 2500080.3 | U33: =S33+L33-R33 -> -1410467.2 | AC33: Ideal
A34: =A33+1 -> 2059 | B34: =B33+1 -> 69 | C34: =L33 -> -3910547.6 | D34: =C34 * $Z$43 -> -195527.38 | E34: =IF(B34>=67, '18 Social Security'!$G$5 * (1 + '02 Assumptions'!$B$5)^(B34 - '03 Client Profile'!$D$5), 0) -> 69200.331 | F34: 319204.75 | G34: =F34-E34 -> 250004.42 | H34: =G34-P34-M34 -> 234527.32 | I34: =H34-49450-$AD$42-$AE$47-$AB$48 -> 143201.94 | J34: =I34-M34 -> 137205.27 | K34: =J34 * 0.15 + SUMPRODUCT(--(J34 > {0, 11079, 26264, 41452, 57542, 72724, 371479, 445771, 742953}), (J34 - {0, 11079, 26264, 41452, 57542, 72724, 371479, 445771, 742953}), {0.01, 0.01, 0.02, 0.02, 0.02, 0.013, 0.01, 0.01, 0.01}) -> 29779.52 | L34: =C34 + D34 - G34-K34 -> -4385858.9 | M34: =M33 -> 5996.6632 | N34: =49500 * (1 + $Z$47)^($A34-2026) -> 95150.455 | O34: 0 | P34: =4500*(1+$Z$47)^(A34-2027)+IF(B34>=55,1000,0) -> 9480.4327 | Q34: =62600*(1+$Z$47)^(A34-2026) -> 120331.69 | S34: =S33*1.03 -> 2575082.8 | U34: =S34+L34-R34 -> -1810776.1 | Y34: NIT threshold | Z34: 200000 | AC34: 200000
A35: =A34+1 -> 2060 | B35: =B34+1 -> 70 | C35: =L34 -> -4385858.9 | D35: =C35 * $Z$43 -> -219292.95 | E35: =IF(B35>=67, '18 Social Security'!$G$5 * (1 + '02 Assumptions'!$B$5)^(B35 - '03 Client Profile'!$D$5), 0) -> 70584.337 | F35: 325588.84 | G35: =F35-E35 -> 255004.51 | H35: =G35-P35-M35 -> 239357.8 | I35: =H35-49450-$AD$42-$AE$47-$AB$48 -> 148032.42 | J35: =I35-M35 -> 142035.75 | K35: =J35 * 0.15 + SUMPRODUCT(--(J35 > {0, 11079, 26264, 41452, 57542, 72724, 371479, 445771, 742953}), (J35 - {0, 11079, 26264, 41452, 57542, 72724, 371479, 445771, 742953}), {0.01, 0.01, 0.02, 0.02, 0.02, 0.013, 0.01, 0.01, 0.01}) -> 30953.326 | L35: =C35 + D35 - G35-K35 -> -4891109.7 | M35: =M34 -> 5996.6632 | N35: =49500 * (1 + $Z$47)^($A35-2026) -> 97053.464 | O35: 0 | P35: =4500*(1+$Z$47)^(A35-2027)+IF(B35>=55,1000,0) -> 9650.0413 | Q35: =62600*(1+$Z$47)^(A35-2026) -> 122738.32 | S35: =S34*1.03 -> 2652335.2 | U35: =S35+L35-R35 -> -2238774.4 | Y35: Standard deduction | Z35: 16100 | AC35: ST/Ordinary | AD35: Capital Gains | AE35: TaxFree | AF35: Total | AH35: Tax | AI35: CA
A36: =A35+1 -> 2061 | B36: =B35+1 -> 71 | C36: =L35 -> -4891109.7 | D36: =C36 * $Z$43 -> -244555.48 | E36: =IF(B36>=67, '18 Social Security'!$G$5 * (1 + '02 Assumptions'!$B$5)^(B36 - '03 Client Profile'!$D$5), 0) -> 71996.024 | F36: 332100.62 | G36: =F36-E36 -> 260104.6 | H36: =G36-P36-M36 -> 244284.89 | I36: =H36-49450-$AD$42-$AE$47-$AB$48 -> 152959.51 | J36: =I36-M36 -> 146962.84 | K36: =J36 * 0.15 + SUMPRODUCT(--(J36 > {0, 11079, 26264, 41452, 57542, 72724, 371479, 445771, 742953}), (J36 - {0, 11079, 26264, 41452, 57542, 72724, 371479, 445771, 742953}), {0.01, 0.01, 0.02, 0.02, 0.02, 0.013, 0.01, 0.01, 0.01}) -> 32150.609 | L36: =C36 + D36 - G36-K36 -> -5427920.4 | M36: =M35 -> 5996.6632 | N36: =49500 * (1 + $Z$47)^($A36-2026) -> 98994.533 | O36: 0 | P36: =4500*(1+$Z$47)^(A36-2027)+IF(B36>=55,1000,0) -> 9823.0421 | Q36: =62600*(1+$Z$47)^(A36-2026) -> 125193.09 | S36: =S35*1.03 -> 2731905.3 | U36: =S36+L36-R36 -> -2696015.1 | Y36: Itemized deductions | Z36: 25000 | AC36: =max(Z35,Z36) -> 25000 | AD36: 162500 | AE36: 3000 | AF36: =SUM(AC36:AE36) -> 190500 | AH36: =(AD36-N2)*0.15 -> 16801.5 | AI36: =(AD36-AC36)*0.093 -> 12787.5
A37: =A36+1 -> 2062 | B37: =B36+1 -> 72 | C37: =L36 -> -5427920.4 | D37: =C37 * $Z$43 -> -271396.02 | E37: =IF(B37>=67, '18 Social Security'!$G$5 * (1 + '02 Assumptions'!$B$5)^(B37 - '03 Client Profile'!$D$5), 0) -> 73435.944 | F37: 338742.63 | G37: =F37-E37 -> 265306.69 | H37: =G37-P37-M37 -> 249310.52 | I37: =H37-49450-$AD$42-$AE$47-$AB$48 -> 157985.14 | J37: =I37-M37 -> 151988.47 | K37: =J37 * 0.15 + SUMPRODUCT(--(J37 > {0, 11079, 26264, 41452, 57542, 72724, 371479, 445771, 742953}), (J37 - {0, 11079, 26264, 41452, 57542, 72724, 371479, 445771, 742953}), {0.01, 0.01, 0.02, 0.02, 0.02, 0.013, 0.01, 0.01, 0.01}) -> 33371.837 | L37: =C37 + D37 - G37-K37 -> -5997994.9 | M37: =M36 -> 5996.6632 | N37: =49500 * (1 + $Z$47)^($A37-2026) -> 100974.42 | O37: 0 | P37: =4500*(1+$Z$47)^(A37-2027)+IF(B37>=55,1000,0) -> 9999.503 | Q37: =62600*(1+$Z$47)^(A37-2026) -> 127696.95 | S37: =S36*1.03 -> 2813862.5 | U37: =S37+L37-R37 -> -3184132.5
A38: =A37+1 -> 2063 | B38: =B37+1 -> 73 | C38: =L37 -> -5997994.9 | D38: =C38 * $Z$43 -> -299899.75 | E38: =IF(B38>=67, '18 Social Security'!$G$5 * (1 + '02 Assumptions'!$B$5)^(B38 - '03 Client Profile'!$D$5), 0) -> 74904.663 | F38: 345517.48 | G38: =F38-E38 -> 270612.82 | H38: =G38-P38-M38 -> 254436.66 | I38: =H38-49450-$AD$42-$AE$47-$AB$48 -> 163111.28 | J38: =I38-M38 -> 157114.62 | K38: =J38 * 0.15 + SUMPRODUCT(--(J38 > {0, 11079, 26264, 41452, 57542, 72724, 371479, 445771, 742953}), (J38 - {0, 11079, 26264, 41452, 57542, 72724, 371479, 445771, 742953}), {0.01, 0.01, 0.02, 0.02, 0.02, 0.013, 0.01, 0.01, 0.01}) -> 34617.49 | L38: =C38 + D38 - G38-K38 -> -6603125 | M38: =M37 -> 5996.6632 | N38: =49500 * (1 + $Z$47)^($A38-2026) -> 102993.91 | O38: 0 | P38: =4500*(1+$Z$47)^(A38-2027)+IF(B38>=55,1000,0) -> 10179.493 | Q38: =62600*(1+$Z$47)^(A38-2026) -> 130250.89 | S38: =S37*1.03 -> 2898278.3 | U38: =S38+L38-R38 -> -3704846.6
A39: =A38+1 -> 2064 | B39: =B38+1 -> 74 | C39: =L38 -> -6603125 | D39: =C39 * $Z$43 -> -330156.25 | E39: =IF(B39>=67, '18 Social Security'!$G$5 * (1 + '02 Assumptions'!$B$5)^(B39 - '03 Client Profile'!$D$5), 0) -> 76402.757 | F39: 352427.83 | G39: =F39-E39 -> 276025.08 | H39: =G39-P39-M39 -> 259665.33 | I39: =H39-49450-$AD$42-$AE$47-$AB$48 -> 168339.95 | J39: =I39-M39 -> 162343.28 | K39: =J39 * 0.15 + SUMPRODUCT(--(J39 > {0, 11079, 26264, 41452, 57542, 72724, 371479, 445771, 742953}), (J39 - {0, 11079, 26264, 41452, 57542, 72724, 371479, 445771, 742953}), {0.01, 0.01, 0.02, 0.02, 0.02, 0.013, 0.01, 0.01, 0.01}) -> 35888.056 | L39: =C39 + D39 - G39-K39 -> -7245194.4 | M39: =M38 -> 5996.6632 | N39: =49500 * (1 + $Z$47)^($A39-2026) -> 105053.79 | O39: 0 | P39: =4500*(1+$Z$47)^(A39-2027)+IF(B39>=55,1000,0) -> 10363.083 | Q39: =62600*(1+$Z$47)^(A39-2026) -> 132855.9 | S39: =S38*1.03 -> 2985226.7 | U39: =S39+L39-R39 -> -4259967.7
A40: =A39+1 -> 2065 | B40: =B39+1 -> 75 | C40: =L39 -> -7245194.4 | D40: =C40 * $Z$43 -> -362259.72 | E40: =IF(B40>=67, '18 Social Security'!$G$5 * (1 + '02 Assumptions'!$B$5)^(B40 - '03 Client Profile'!$D$5), 0) -> 77930.812 | F40: 359476.39 | G40: =F40-E40 -> 281545.58 | H40: =G40-P40-M40 -> 264998.57 | I40: =H40-49450-$AD$42-$AE$47-$AB$48 -> 173673.19 | J40: =I40-M40 -> 167676.52 | K40: =J40 * 0.15 + SUMPRODUCT(--(J40 > {0, 11079, 26264, 41452, 57542, 72724, 371479, 445771, 742953}), (J40 - {0, 11079, 26264, 41452, 57542, 72724, 371479, 445771, 742953}), {0.01, 0.01, 0.02, 0.02, 0.02, 0.013, 0.01, 0.01, 0.01}) -> 37184.033 | L40: =C40 + D40 - G40-K40 -> -7926183.7 | M40: =M39 -> 5996.6632 | N40: =49500 * (1 + $Z$47)^($A40-2026) -> 107154.87 | O40: 0 | P40: =4500*(1+$Z$47)^(A40-2027)+IF(B40>=55,1000,0) -> 10550.345 | Q40: =62600*(1+$Z$47)^(A40-2026) -> 135513.02 | S40: =S39*1.03 -> 3074783.5 | U40: =S40+L40-R40 -> -4851400.2
A41: =A40+1 -> 2066 | B41: =B40+1 -> 76 | C41: =L40 -> -7926183.7 | D41: =C41 * $Z$43 -> -396309.18 | E41: =IF(B41>=67, '18 Social Security'!$G$5 * (1 + '02 Assumptions'!$B$5)^(B41 - '03 Client Profile'!$D$5), 0) -> 79489.428 | F41: 366665.92 | G41: =F41-E41 -> 287176.49 | H41: =G41-P41-M41 -> 270438.48 | I41: =H41-49450-$AD$42-$AE$47-$AB$48 -> 179113.09 | J41: =I41-M41 -> 173116.43 | K41: =J41 * 0.15 + SUMPRODUCT(--(J41 > {0, 11079, 26264, 41452, 57542, 72724, 371479, 445771, 742953}), (J41 - {0, 11079, 26264, 41452, 57542, 72724, 371479, 445771, 742953}), {0.01, 0.01, 0.02, 0.02, 0.02, 0.013, 0.01, 0.01, 0.01}) -> 38505.93 | L41: =C41 + D41 - G41-K41 -> -8648175.3 | M41: =M40 -> 5996.6632 | N41: =49500 * (1 + $Z$47)^($A41-2026) -> 109297.96 | O41: 0 | P41: =4500*(1+$Z$47)^(A41-2027)+IF(B41>=55,1000,0) -> 10741.351 | Q41: =62600*(1+$Z$47)^(A41-2026) -> 138223.28 | S41: =S40*1.03 -> 3167027 | U41: =S41+L41-R41 -> -5481148.3 | AB41: Spacex, etc. | AC41: Total Cost Basis | AD41: Total/yr | AE41: Cost Basis left
A42: =A41+1 -> 2067 | B42: =B41+1 -> 77 | C42: =L41 -> -8648175.3 | D42: =C42 * $Z$43 -> -432408.76 | E42: =IF(B42>=67, '18 Social Security'!$G$5 * (1 + '02 Assumptions'!$B$5)^(B42 - '03 Client Profile'!$D$5), 0) -> 81079.216 | F42: 373999.24 | G42: =F42-E42 -> 292920.02 | H42: =G42-P42-M42 -> 275987.18 | I42: =H42-49450-$AD$42-$AE$47-$AB$48 -> 184661.8 | J42: =I42-M42 -> 178665.13 | K42: =J42 * 0.15 + SUMPRODUCT(--(J42 > {0, 11079, 26264, 41452, 57542, 72724, 371479, 445771, 742953}), (J42 - {0, 11079, 26264, 41452, 57542, 72724, 371479, 445771, 742953}), {0.01, 0.01, 0.02, 0.02, 0.02, 0.013, 0.01, 0.01, 0.01}) -> 39854.265 | L42: =C42 + D42 - G42-K42 -> -9413358.3 | M42: =M41 -> 5996.6632 | N42: =49500 * (1 + $Z$47)^($A42-2026) -> 111483.92 | O42: 0 | P42: =4500*(1+$Z$47)^(A42-2027)+IF(B42>=55,1000,0) -> 10936.178 | Q42: =62600*(1+$Z$47)^(A42-2026) -> 140987.75 | S42: =S41*1.03 -> 3262037.8 | U42: =S42+L42-R42 -> -6151320.5 | Y42: Configuration | AC42: =SUM('Tax Lots'!F2:'Tax Lots'!F126) -> 353803.13 | AD42: =AC42/59 -> 5996.6632 | AE42: =AC42-sum(M2:M126) -> -2.3283064e-10
A43: =A42+1 -> 2068 | B43: =B42+1 -> 78 | C43: =L42 -> -9413358.3 | D43: =C43 * $Z$43 -> -470667.92 | E43: =IF(B43>=67, '18 Social Security'!$G$5 * (1 + '02 Assumptions'!$B$5)^(B43 - '03 Client Profile'!$D$5), 0) -> 82700.801 | F43: 381479.22 | G43: =F43-E43 -> 298778.42 | H43: =G43-P43-M43 -> 281646.86 | I43: =H43-49450-$AD$42-$AE$47-$AB$48 -> 190321.47 | J43: =I43-M43 -> 184324.81 | K43: =J43 * 0.15 + SUMPRODUCT(--(J43 > {0, 11079, 26264, 41452, 57542, 72724, 371479, 445771, 742953}), (J43 - {0, 11079, 26264, 41452, 57542, 72724, 371479, 445771, 742953}), {0.01, 0.01, 0.02, 0.02, 0.02, 0.013, 0.01, 0.01, 0.01}) -> 41229.567 | L43: =C43 + D43 - G43-K43 -> -10224034 | M43: =M42 -> 5996.6632 | N43: =49500 * (1 + $Z$47)^($A43-2026) -> 113713.6 | O43: 0 | P43: =4500*(1+$Z$47)^(A43-2027)+IF(B43>=55,1000,0) -> 11134.902 | Q43: =62600*(1+$Z$47)^(A43-2026) -> 143807.5 | S43: =S42*1.03 -> 3359898.9 | U43: =S43+L43-R43 -> -6864135.3 | Y43: Rate of Return | Z43: 0.05 | AB43: 401k
A44: =A43+1 -> 2069 | B44: =B43+1 -> 79 | C44: =L43 -> -10224034 | D44: =C44 * $Z$43 -> -511201.71 | E44: =IF(B44>=67, '18 Social Security'!$G$5 * (1 + '02 Assumptions'!$B$5)^(B44 - '03 Client Profile'!$D$5), 0) -> 84354.817 | F44: 389108.81 | G44: =F44-E44 -> 304753.99 | H44: =G44-P44-M44 -> 287419.73 | I44: =H44-49450-$AD$42-$AE$47-$AB$48 -> 196094.34 | J44: =I44-M44 -> 190097.68 | K44: =J44 * 0.15 + SUMPRODUCT(--(J44 > {0, 11079, 26264, 41452, 57542, 72724, 371479, 445771, 742953}), (J44 - {0, 11079, 26264, 41452, 57542, 72724, 371479, 445771, 742953}), {0.01, 0.01, 0.02, 0.02, 0.02, 0.013, 0.01, 0.01, 0.01}) -> 42632.374 | L44: =C44 + D44 - G44-K44 -> -11082622 | M44: =M43 -> 5996.6632 | N44: =49500 * (1 + $Z$47)^($A44-2026) -> 115987.87 | O44: 0 | P44: =4500*(1+$Z$47)^(A44-2027)+IF(B44>=55,1000,0) -> 11337.6 | Q44: =62600*(1+$Z$47)^(A44-2026) -> 146683.65 | S44: =S43*1.03 -> 3460695.9 | U44: =S44+L44-R44 -> -7621926.4 | Y44: MAGI Goal | Z44: 62000 | AB44: HSA/Roth
A45: =A44+1 -> 2070 | B45: =B44+1 -> 80 | C45: =L44 -> -11082622 | D45: =C45 * $Z$43 -> -554131.12 | E45: =IF(B45>=67, '18 Social Security'!$G$5 * (1 + '02 Assumptions'!$B$5)^(B45 - '03 Client Profile'!$D$5), 0) -> 86041.913 | F45: 396890.98 | G45: =F45-E45 -> 310849.07 | H45: =G45-P45-M45 -> 293308.05 | I45: =H45-49450-$AD$42-$AE$47-$AB$48 -> 201982.67 | J45: =I45-M45 -> 195986.01 | K45: =J45 * 0.15 + SUMPRODUCT(--(J45 > {0, 11079, 26264, 41452, 57542, 72724, 371479, 445771, 742953}), (J45 - {0, 11079, 26264, 41452, 57542, 72724, 371479, 445771, 742953}), {0.01, 0.01, 0.02, 0.02, 0.02, 0.013, 0.01, 0.01, 0.01}) -> 44063.238 | L45: =C45 + D45 - G45-K45 -> -11991666 | M45: =M44 -> 5996.6632 | N45: =49500 * (1 + $Z$47)^($A45-2026) -> 118307.63 | O45: 0 | P45: =4500*(1+$Z$47)^(A45-2027)+IF(B45>=55,1000,0) -> 11544.352 | Q45: =62600*(1+$Z$47)^(A45-2026) -> 149617.33 | S45: =S44*1.03 -> 3564516.8 | U45: =S45+L45-R45 -> -8427149 | Y45: AGI Goal | Z45: 49000 | AD45: 0 | AE45: 0.15 | AG45: California
A46: =A45+1 -> 2071 | B46: =B45+1 -> 81 | C46: =L45 -> -11991666 | D46: =C46 * $Z$43 -> -599583.29 | E46: =IF(B46>=67, '18 Social Security'!$G$5 * (1 + '02 Assumptions'!$B$5)^(B46 - '03 Client Profile'!$D$5), 0) -> 87762.751 | F46: 404828.8 | G46: =F46-E46 -> 317066.05 | H46: =G46-P46-M46 -> 299314.15 | I46: =H46-49450-$AD$42-$AE$47-$AB$48 -> 207988.76 | J46: =I46-M46 -> 201992.1 | K46: =J46 * 0.15 + SUMPRODUCT(--(J46 > {0, 11079, 26264, 41452, 57542, 72724, 371479, 445771, 742953}), (J46 - {0, 11079, 26264, 41452, 57542, 72724, 371479, 445771, 742953}), {0.01, 0.01, 0.02, 0.02, 0.02, 0.013, 0.01, 0.01, 0.01}) -> 45522.719 | L46: =C46 + D46 - G46-K46 -> -12953838 | M46: =M45 -> 5996.6632 | N46: =49500 * (1 + $Z$47)^($A46-2026) -> 120673.78 | O46: 0 | P46: =4500*(1+$Z$47)^(A46-2027)+IF(B46>=55,1000,0) -> 11755.239 | Q46: =62600*(1+$Z$47)^(A46-2026) -> 152609.67 | S46: =S45*1.03 -> 3671452.3 | U46: =S46+L46-R46 -> -9282385.5 | Y46: Total Income Target | Z46: 150000 | AB46: Tax Rate | AD46: $0 – $49,450 | AE46: $49,451 – $545,500 | AG46: 0.1
A47: =A46+1 -> 2072 | B47: =B46+1 -> 82 | C47: =L46 -> -12953838 | D47: =C47 * $Z$43 -> -647691.89 | E47: =IF(B47>=67, '18 Social Security'!$G$5 * (1 + '02 Assumptions'!$B$5)^(B47 - '03 Client Profile'!$D$5), 0) -> 89518.006 | F47: 412925.38 | G47: =F47-E47 -> 323407.37 | H47: =G47-P47-M47 -> 305440.36 | I47: =H47-49450-$AD$42-$AE$47-$AB$48 -> 214114.98 | J47: =I47-M47 -> 208118.32 | K47: =J47 * 0.15 + SUMPRODUCT(--(J47 > {0, 11079, 26264, 41452, 57542, 72724, 371479, 445771, 742953}), (J47 - {0, 11079, 26264, 41452, 57542, 72724, 371479, 445771, 742953}), {0.01, 0.01, 0.02, 0.02, 0.02, 0.013, 0.01, 0.01, 0.01}) -> 47011.389 | L47: =C47 + D47 - G47-K47 -> -13971948 | M47: =M46 -> 5996.6632 | N47: =49500 * (1 + $Z$47)^($A47-2026) -> 123087.26 | O47: 0 | P47: =4500*(1+$Z$47)^(A47-2027)+IF(B47>=55,1000,0) -> 11970.344 | Q47: =62600*(1+$Z$47)^(A47-2026) -> 155661.87 | S47: =S46*1.03 -> 3781595.8 | U47: =S47+L47-R47 -> -10190353 | Y47: Inflation | Z47: ='02 Assumptions'!B5 -> 0.02 | AB47: Deductions | AD47: Property tax | AE47: 13000
A48: =A47+1 -> 2073 | B48: =B47+1 -> 83 | C48: =L47 -> -13971948 | D48: =C48 * $Z$43 -> -698597.42 | E48: =IF(B48>=67, '18 Social Security'!$G$5 * (1 + '02 Assumptions'!$B$5)^(B48 - '03 Client Profile'!$D$5), 0) -> 91308.367 | F48: 421183.89 | G48: =F48-E48 -> 329875.52 | H48: =G48-P48-M48 -> 311689.1 | I48: =H48-49450-$AD$42-$AE$47-$AB$48 -> 220363.72 | J48: =I48-M48 -> 214367.06 | K48: =J48 * 0.15 + SUMPRODUCT(--(J48 > {0, 11079, 26264, 41452, 57542, 72724, 371479, 445771, 742953}), (J48 - {0, 11079, 26264, 41452, 57542, 72724, 371479, 445771, 742953}), {0.01, 0.01, 0.02, 0.02, 0.02, 0.013, 0.01, 0.01, 0.01}) -> 48529.833 | L48: =C48 + D48 - G48-K48 -> -15048951 | M48: =M47 -> 5996.6632 | N48: =49500 * (1 + $Z$47)^($A48-2026) -> 125549 | O48: 0 | P48: =4500*(1+$Z$47)^(A48-2027)+IF(B48>=55,1000,0) -> 12189.751 | Q48: =62600*(1+$Z$47)^(A48-2026) -> 158775.1 | S48: =S47*1.03 -> 3895043.7 | U48: =S48+L48-R48 -> -11153908 | AA48: Mortgage interest | AB48: =1906.56*12 -> 22878.72 | AD48: 11832
A49: =A48+1 -> 2074 | B49: =B48+1 -> 84 | C49: =L48 -> -15048951 | D49: =C49 * $Z$43 -> -752447.56 | E49: =IF(B49>=67, '18 Social Security'!$G$5 * (1 + '02 Assumptions'!$B$5)^(B49 - '03 Client Profile'!$D$5), 0) -> 93134.534 | F49: 429607.56 | G49: =F49-E49 -> 336473.03 | H49: =G49-P49-M49 -> 318062.82 | I49: =H49-49450-$AD$42-$AE$47-$AB$48 -> 226737.44 | J49: =I49-M49 -> 220740.77 | K49: =J49 * 0.15 + SUMPRODUCT(--(J49 > {0, 11079, 26264, 41452, 57542, 72724, 371479, 445771, 742953}), (J49 - {0, 11079, 26264, 41452, 57542, 72724, 371479, 445771, 742953}), {0.01, 0.01, 0.02, 0.02, 0.02, 0.013, 0.01, 0.01, 0.01}) -> 50078.646 | L49: =C49 + D49 - G49-K49 -> -16187950 | M49: =M48 -> 5996.6632 | N49: =49500 * (1 + $Z$47)^($A49-2026) -> 128059.98 | O49: 0 | P49: =4500*(1+$Z$47)^(A49-2027)+IF(B49>=55,1000,0) -> 12413.546 | Q49: =62600*(1+$Z$47)^(A49-2026) -> 161950.61 | S49: =S48*1.03 -> 4011895 | U49: =S49+L49-R49 -> -12176055 | Y49: CA tax | AD49: Interest | AE49: Yrs left | AF49: Payment
...

Sheet Meeting notes
A1: 46213
B2: Lockout shares period
C3: Google until you leave you can't do options | F3: Create a Rule 10b5-1 trading plan
B5: Spending/income
C6: Lets update the cashflow sheet
B8: Volatility Strategy
C9: Options education | E9: https://youtu.be/gWp3op51ZzI | G9: https://youtu.be/hK_MP1RRU9w?list=PL8a6s5nq1lPRcGlhhMLSqx1BK1rttI00R
B10: Buy | C10: Puts | D10: Insurance | E10: You pay the premium
B11: sell | C11: Calls | D11: Income | E11: against shares you hold
B13: MAGI
C14: Only deductions are HSA, IRA against earned income(so never lowers MAGI)
C15: Business losses, Captial Gain losses.
C16: Max capital gain loss is $3k a year but carry over to future years if you go over.
B18: 1 Year Emergency Fund
C19: Low volatility low return just to make sure you always have 1 year available | H19: We will figure out how much
D20: SGOV or FLOT
A23: 46230 | C23: Intro | D23: Details
B24: Discount Cash Flow | C24: https://youtu.be/J8E64j-2pvc?si=7tfpNpnxoiDXXcuD | D24: https://youtu.be/CfkFFk-r9aA?si=mec-m6_s463gHC_2
C25: "How much should I pay today for the cash this business will generate in the future?"
C27: Imagine a magic machine that prints $100 a year for the next 10 years, and then it breaks. In total, it will print $1,000.
C29: If your neighbor offers to sell you this machine, what is a fair price?
C31: You definitely would not pay $1,000 for it. Why? Because you have to wait a full 10 years to get all your money. If you have $1,000 today, you could just put it in a savings account or an index fund, earn interest, and have way more than $1,000 in a decade.
C33: Because of that wait time, future money is worth less than present money. So, to buy that machine, you demand a discount for the wait. Maybe you decide you are only willing to pay $700 for it today.
C35: That thought process is exactly what a DCF model does for a stock, just with a few more moving parts.
B37: Types of income
C38: Income Bucket | D38: Tax Brackets Applied | E38: Subject to Payroll Taxes? | F38: Can be offset by Capital Losses?
C39: Earned Income | D39: Standard (Graduated) | E39: Yes (Social Security/Medicare) | F39: No
C41: Unearned Ordinary | D41: Standard (Graduated) | E41: No | F41: No
C42: Short-Term Capital Gains | D42: Standard (Graduated) | E42: No | F42: Yes
C43: Long-Term Capital Gains | D43: Preferential (0%, 15%, or 20%) | E43: No | F43: Yes
B45: Social Security
C46: Get your estimate
B48: Real estate
C49: No need for an LLC unless you have many properties
C50: Live in the home for 2 of 5 years for $250k exclusion on the capital gains
C51: Rent for 3 years and then sell it
C52: If you rent it beyond the 3 years you would lose the exclusion
C54: Earned income
D55: Things like bed and breakfast or AirBnB where you are providing services as well
C56: Unearned incom | D56: Rent
...

Sheet Yearly Breakdown
A3: Category | B3: Item | C3: 2027 | D3: 2028 | E3: 2029 | F3: 2030 | G3: 2031 | H3: 2032 | I3: 2033 | J3: 2034 | K3: 2035 | L3: 2036 | M3: 2037
A4: Summary | B4: Beginning Balance | C4: =VLOOKUP(C$3, 'Retirement Projection'!$A:$U, 3, FALSE) -> 2912398 | D4: =VLOOKUP(D$3, 'Retirement Projection'!$A:$U, 3, FALSE) -> 2874574.7 | E4: =VLOOKUP(E$3, 'Retirement Projection'!$A:$U, 3, FALSE) -> 2833233.4 | F4: =VLOOKUP(F$3, 'Retirement Projection'!$A:$U, 3, FALSE) -> 2785596 | G4: =VLOOKUP(G$3, 'Retirement Projection'!$A:$U, 3, FALSE) -> 2731263.2 | H4: =VLOOKUP(H$3, 'Retirement Projection'!$A:$U, 3, FALSE) -> 2669782.4 | I4: =VLOOKUP(I$3, 'Retirement Projection'!$A:$U, 3, FALSE) -> 2600693.2 | J4: =VLOOKUP(J$3, 'Retirement Projection'!$A:$U, 3, FALSE) -> 2523524.7 | ... M4: =VLOOKUP(M$3, 'Retirement Projection'!$A:$U, 3, FALSE) -> 2238443.6
B5: Ending Balance | C5: =VLOOKUP(C$3, 'Retirement Projection'!$A:$U, 12, FALSE) -> 2874574.7 | D5: =VLOOKUP(D$3, 'Retirement Projection'!$A:$U, 12, FALSE) -> 2833233.4 | E5: =VLOOKUP(E$3, 'Retirement Projection'!$A:$U, 12, FALSE) -> 2785596 | F5: =VLOOKUP(F$3, 'Retirement Projection'!$A:$U, 12, FALSE) -> 2731263.2 | G5: =VLOOKUP(G$3, 'Retirement Projection'!$A:$U, 12, FALSE) -> 2669782.4 | H5: =VLOOKUP(H$3, 'Retirement Projection'!$A:$U, 12, FALSE) -> 2600693.2 | I5: =VLOOKUP(I$3, 'Retirement Projection'!$A:$U, 12, FALSE) -> 2523524.7 | J5: =VLOOKUP(J$3, 'Retirement Projection'!$A:$U, 12, FALSE) -> 2437780.4 | ... M5: =VLOOKUP(M$3, 'Retirement Projection'!$A:$U, 12, FALSE) -> 2123719.2
B6: Networth | C6: =VLOOKUP(C$3, 'Retirement Projection'!$A:$U, 21, FALSE) -> 3502436.3 | D6: =VLOOKUP(D$3, 'Retirement Projection'!$A:$U, 21, FALSE) -> 3496231 | E6: =VLOOKUP(E$3, 'Retirement Projection'!$A:$U, 21, FALSE) -> 3484932.8 | F6: =VLOOKUP(F$3, 'Retirement Projection'!$A:$U, 21, FALSE) -> 3468187.4 | G6: =VLOOKUP(G$3, 'Retirement Projection'!$A:$U, 21, FALSE) -> 3445588.8 | H6: =VLOOKUP(H$3, 'Retirement Projection'!$A:$U, 21, FALSE) -> 3416725.6 | I6: =VLOOKUP(I$3, 'Retirement Projection'!$A:$U, 21, FALSE) -> 3381177.3 | J6: =VLOOKUP(J$3, 'Retirement Projection'!$A:$U, 21, FALSE) -> 3338500.6 | ... M6: =VLOOKUP(M$3, 'Retirement Projection'!$A:$U, 21, FALSE) -> 3162889.2
A8: Income | B8: Earned income | C8: 0 | D8: 0 | E8: 0 | F8: 0 | G8: 0 | H8: 0 | I8: 0 | J8: 0 | K8: 0 | L8: 0 | M8: 0
A9: Income | B9: Dividends (60 day hold) | C9: 0 | D9: 0 | E9: 0 | F9: 0 | G9: 0 | H9: 0 | I9: 0 | J9: 0 | K9: 0 | L9: 0 | M9: 0
A10: Income | B10: Rental | C10: 0 | D10: 0 | E10: 0 | F10: 0 | G10: 0 | H10: 0 | I10: 0 | J10: 0 | K10: 0 | L10: 0 | M10: 0
A11: Income | B11: Options | C11: 0 | D11: 0 | E11: 0 | F11: 0 | G11: 0 | H11: 0 | I11: 0 | J11: 0 | K11: 0 | L11: 0 | M11: 0
A12: Income | B12: Interest | C12: 0 | D12: 0 | E12: 0 | F12: 0 | G12: 0 | H12: 0 | I12: 0 | J12: 0 | K12: 0 | L12: 0 | M12: 0
A13: Income | B13: Other | C13: 0 | D13: 0 | E13: 0 | F13: 0 | G13: 0 | H13: 0 | I13: 0 | J13: 0 | K13: 0 | L13: 0 | M13: 0
A14: Income | B14: GOOG Sales Income | C14: =SUMIFS(C$48:C$1083, $B$48:$B$1083, "Realized Gain/Loss") -> 170326.48 | D14: =SUMIFS(D$48:D$1083, $B$48:$B$1083, "Realized Gain/Loss") -> 90196.919 | E14: =SUMIFS(E$48:E$1083, $B$48:$B$1083, "Realized Gain/Loss") -> 0 | F14: =SUMIFS(F$48:F$1083, $B$48:$B$1083, "Realized Gain/Loss") -> 0 | G14: =SUMIFS(G$48:G$1083, $B$48:$B$1083, "Realized Gain/Loss") -> 0 | H14: =SUMIFS(H$48:H$1083, $B$48:$B$1083, "Realized Gain/Loss") -> 0 | I14: =SUMIFS(I$48:I$1083, $B$48:$B$1083, "Realized Gain/Loss") -> 0 | J14: =SUMIFS(J$48:J$1083, $B$48:$B$1083, "Realized Gain/Loss") -> 0 | ... M14: =SUMIFS(M$48:M$1083, $B$48:$B$1083, "Realized Gain/Loss") -> 0
A15: Income | B15: SPCX Sales Income | C15: =SUMIFS(C$1085:C$1134, $B$1085:$B$1134, "Realized Gain/Loss") -> 0 | D15: =SUMIFS(D$1085:D$1134, $B$1085:$B$1134, "Realized Gain/Loss") -> 0 | E15: =SUMIFS(E$1085:E$1134, $B$1085:$B$1134, "Realized Gain/Loss") -> 171248 | F15: =SUMIFS(F$1085:F$1134, $B$1085:$B$1134, "Realized Gain/Loss") -> 175140 | G15: =SUMIFS(G$1085:G$1134, $B$1085:$B$1134, "Realized Gain/Loss") -> 180005 | H15: =SUMIFS(H$1085:H$1134, $B$1085:$B$1134, "Realized Gain/Loss") -> 182437.5 | I15: =SUMIFS(I$1085:I$1134, $B$1085:$B$1134, "Realized Gain/Loss") -> 184870 | J15: =SUMIFS(J$1085:J$1134, $B$1085:$B$1134, "Realized Gain/Loss") -> 189735 | ... M15: =SUMIFS(M$1085:M$1134, $B$1085:$B$1134, "Realized Gain/Loss") -> 201897.5
A16: Income | B16: Tax-Free Principal from Sales | C16: =SUMIFS(C$48:C2072, $B$48:$B2072, "Cost Basis Used") -> 120835.37 | D16: =SUMIFS(D$48:D2072, $B$48:$B2072, "Cost Basis Used") -> 92973.481 | E16: =SUMIFS(E$48:E2072, $B$48:$B2072, "Cost Basis Used") -> 4752 | F16: =SUMIFS(F$48:F2072, $B$48:$B2072, "Cost Basis Used") -> 4860 | G16: =SUMIFS(G$48:G2072, $B$48:$B2072, "Cost Basis Used") -> 4995 | H16: =SUMIFS(H$48:H2072, $B$48:$B2072, "Cost Basis Used") -> 5062.5 | I16: =SUMIFS(I$48:I2072, $B$48:$B2072, "Cost Basis Used") -> 5130 | J16: =SUMIFS(J$48:J2072, $B$48:$B2072, "Cost Basis Used") -> 5265 | ... M16: =SUMIFS(M$48:M2072, $B$48:$B2072, "Cost Basis Used") -> 5602.5
A17: Income | B17: Total Income | C17: =C14+C9+C10+C11+C12+C13+C8 -> 170326.48 | D17: =SUM(D9:D16) -> 183170.4 | E17: =SUM(E9:E16) -> 176000 | F17: =SUM(F9:F16) -> 180000 | G17: =SUM(G9:G16) -> 185000 | H17: =SUM(H9:H16) -> 187500 | I17: =SUM(I9:I16) -> 190000 | J17: =SUM(J9:J16) -> 195000 | K17: =SUM(K9:K16) -> 197500 | ... M17: =SUM(M9:M16) -> 207500
A19: Taxes | B19: Earned | C19: =C8 -> 0 | D19: =D8 -> 0 | E19: =E8 -> 0 | F19: =F8 -> 0 | G19: =G8 -> 0 | H19: =H8 -> 0 | I19: =I8 -> 0 | J19: =J8 -> 0 | ... M19: =M8 -> 0
B20: Unearned | C20: =C10+C11+C12 -> 0 | D20: =D10+D11+D12 -> 0 | E20: =E10+E11+E12 -> 0 | F20: =F10+F11+F12 -> 0 | G20: =G10+G11+G12 -> 0 | H20: =H10+H11+H12 -> 0 | I20: =I10+I11+I12 -> 0 | J20: =J10+J11+J12 -> 0 | ... M20: =M10+M11+M12 -> 0
B21: Short Term CapGains
B22: Long Term CapGains | C22: =(C14+C15)-C16 -> 49491.12 | D22: =(D14+D15)-D16 -> -2776.5615 | E22: =(E14+E15)-E16 -> 166496 | F22: =(F14+F15)-F16 -> 170280 | G22: =(G14+G15)-G16 -> 175010 | H22: =(H14+H15)-H16 -> 177375 | I22: =(I14+I15)-I16 -> 179740 | J22: =(J14+J15)-J16 -> 184470 | ... M22: =(M14+M15)-M16 -> 196295
A24: Deductions | B24: SALT
B25: CAP Gains | C25: ='Retirement Projection'!N2 -> 50490 | D25: ='Retirement Projection'!N3 -> 51499.8 | E25: ='Retirement Projection'!N4 -> 52529.796 | F25: ='Retirement Projection'!N5 -> 53580.392 | G25: ='Retirement Projection'!N6 -> 54652 | H25: ='Retirement Projection'!N7 -> 55745.04 | I25: ='Retirement Projection'!N8 -> 56859.941 | J25: ='Retirement Projection'!N9 -> 57997.139 | K25: ='Retirement Projection'!N10 -> 59157.082 | L25: ='Retirement Projection'!N11 -> 60340.224 | M25: ='Retirement Projection'!N12 -> 61547.028
A27: AGI | C27: =C22-C25 -> -998.88038 | D27: =D22-D25 -> -54276.361 | E27: =E22-E25 -> 113966.2 | F27: =F22-F25 -> 116699.61 | G27: =G22-G25 -> 120358 | H27: =H22-H25 -> 121629.96 | I27: =I22-I25 -> 122880.06 | J27: =J22-J25 -> 126472.86 | ... M27: =M22-M25 -> 134747.97
A29: Expense | B29: Total Expense | C29: =SUM(C30:C35) -> 169380.67 | D29: =SUM(D30:D35) -> 172768.28 | E29: =SUM(E30:E35) -> 176223.65 | F29: =SUM(F30:F35) -> 179748.12 | G29: =SUM(G30:G35) -> 183343.08 | H29: =SUM(H30:H35) -> 187009.95 | I29: =SUM(I30:I35) -> 190750.14 | J29: =SUM(J30:J35) -> 194565.15 | ... M29: =SUM(M30:M35) -> 206474.09
A30: {=IF(B30:B35<>"", "Expense", "")} -> Expense | B30: =IFERROR(__xludf.DUMMYFUNCTION("UNIQUE(FILTER('05 Cash Flow'!B5:B2072, '05 Cash Flow'!A5:A2072=""Expense""))"),"Mortgage") -> Mortgage | C30: =IF($B30="","", SUMIFS('05 Cash Flow'!$G:$G, '05 Cash Flow'!$B:$B, $B30) * (1 + '02 Assumptions'!$B$5)) -> 28571.71 | D30: =IF($B30="","", C30 * (1 + '02 Assumptions'!$B$5)) -> 29143.144 | E30: =IF($B30="","", D30 * (1 + '02 Assumptions'!$B$5)) -> 29726.007 | F30: =IF($B30="","", E30 * (1 + '02 Assumptions'!$B$5)) -> 30320.527 | G30: =IF($B30="","", F30 * (1 + '02 Assumptions'!$B$5)) -> 30926.937 | H30: =IF($B30="","", G30 * (1 + '02 Assumptions'!$B$5)) -> 31545.476 | I30: =IF($B30="","", H30 * (1 + '02 Assumptions'!$B$5)) -> 32176.386 | J30: =IF($B30="","", I30 * (1 + '02 Assumptions'!$B$5)) -> 32819.913 | K30: =IF($B30="","", J30 * (1 + '02 Assumptions'!$B$5)) -> 33476.312 | ... M30: =IF($B30="","", L30 * (1 + '02 Assumptions'!$B$5)) -> 34828.755
A31: Expense | B31: =IFERROR(__xludf.DUMMYFUNCTION("""COMPUTED_VALUE"""),"Home") -> Home | C31: =IF($B31="","", SUMIFS('05 Cash Flow'!$G:$G, '05 Cash Flow'!$B:$B, $B31) * (1 + '02 Assumptions'!$B$5)) -> 71432.64 | D31: =IF($B31="","", C31 * (1 + '02 Assumptions'!$B$5)) -> 72861.293 | E31: =IF($B31="","", D31 * (1 + '02 Assumptions'!$B$5)) -> 74318.519 | F31: =IF($B31="","", E31 * (1 + '02 Assumptions'!$B$5)) -> 75804.889 | G31: =IF($B31="","", F31 * (1 + '02 Assumptions'!$B$5)) -> 77320.987 | H31: =IF($B31="","", G31 * (1 + '02 Assumptions'!$B$5)) -> 78867.407 | I31: =IF($B31="","", H31 * (1 + '02 Assumptions'!$B$5)) -> 80444.755 | J31: =IF($B31="","", I31 * (1 + '02 Assumptions'!$B$5)) -> 82053.65 | K31: =IF($B31="","", J31 * (1 + '02 Assumptions'!$B$5)) -> 83694.723 | ... M31: =IF($B31="","", L31 * (1 + '02 Assumptions'!$B$5)) -> 87075.99
A32: Expense | B32: =IFERROR(__xludf.DUMMYFUNCTION("""COMPUTED_VALUE"""),"Groceries") -> Groceries | C32: =IF($B32="","", SUMIFS('05 Cash Flow'!$G:$G, '05 Cash Flow'!$B:$B, $B32) * (1 + '02 Assumptions'!$B$5)) -> 12509.28 | D32: =IF($B32="","", C32 * (1 + '02 Assumptions'!$B$5)) -> 12759.466 | E32: =IF($B32="","", D32 * (1 + '02 Assumptions'!$B$5)) -> 13014.655 | F32: =IF($B32="","", E32 * (1 + '02 Assumptions'!$B$5)) -> 13274.948 | G32: =IF($B32="","", F32 * (1 + '02 Assumptions'!$B$5)) -> 13540.447 | H32: =IF($B32="","", G32 * (1 + '02 Assumptions'!$B$5)) -> 13811.256 | I32: =IF($B32="","", H32 * (1 + '02 Assumptions'!$B$5)) -> 14087.481 | J32: =IF($B32="","", I32 * (1 + '02 Assumptions'!$B$5)) -> 14369.231 | K32: =IF($B32="","", J32 * (1 + '02 Assumptions'!$B$5)) -> 14656.615 | ... M32: =IF($B32="","", L32 * (1 + '02 Assumptions'!$B$5)) -> 15248.743
A33: Expense | B33: =IFERROR(__xludf.DUMMYFUNCTION("""COMPUTED_VALUE"""),"Shopping/Entertainment") -> Shopping/Entertainment | C33: =IF($B33="","", SUMIFS('05 Cash Flow'!$G:$G, '05 Cash Flow'!$B:$B, $B33) * (1 + '02 Assumptions'!$B$5)) -> 28152 | D33: =IF($B33="","", C33 * (1 + '02 Assumptions'!$B$5)) -> 28715.04 | E33: =IF($B33="","", D33 * (1 + '02 Assumptions'!$B$5)) -> 29289.341 | F33: =IF($B33="","", E33 * (1 + '02 Assumptions'!$B$5)) -> 29875.128 | G33: =IF($B33="","", F33 * (1 + '02 Assumptions'!$B$5)) -> 30472.63 | H33: =IF($B33="","", G33 * (1 + '02 Assumptions'!$B$5)) -> 31082.083 | I33: =IF($B33="","", H33 * (1 + '02 Assumptions'!$B$5)) -> 31703.724 | J33: =IF($B33="","", I33 * (1 + '02 Assumptions'!$B$5)) -> 32337.799 | K33: =IF($B33="","", J33 * (1 + '02 Assumptions'!$B$5)) -> 32984.555 | ... M33: =IF($B33="","", L33 * (1 + '02 Assumptions'!$B$5)) -> 34317.131
A34: Expense | B34: =IFERROR(__xludf.DUMMYFUNCTION("""COMPUTED_VALUE"""),"Other") -> Other | C34: =IF($B34="","", SUMIFS('05 Cash Flow'!$G:$G, '05 Cash Flow'!$B:$B, $B34) * (1 + '02 Assumptions'!$B$5)) -> 10355.04 | D34: =IF($B34="","", C34 * (1 + '02 Assumptions'!$B$5)) -> 10562.141 | E34: =IF($B34="","", D34 * (1 + '02 Assumptions'!$B$5)) -> 10773.384 | F34: =IF($B34="","", E34 * (1 + '02 Assumptions'!$B$5)) -> 10988.851 | G34: =IF($B34="","", F34 * (1 + '02 Assumptions'!$B$5)) -> 11208.628 | H34: =IF($B34="","", G34 * (1 + '02 Assumptions'!$B$5)) -> 11432.801 | I34: =IF($B34="","", H34 * (1 + '02 Assumptions'!$B$5)) -> 11661.457 | J34: =IF($B34="","", I34 * (1 + '02 Assumptions'!$B$5)) -> 11894.686 | K34: =IF($B34="","", J34 * (1 + '02 Assumptions'!$B$5)) -> 12132.58 | ... M34: =IF($B34="","", L34 * (1 + '02 Assumptions'!$B$5)) -> 12622.736
A35: Expense | B35: =IFERROR(__xludf.DUMMYFUNCTION("""COMPUTED_VALUE"""),"Health") -> Health | C35: =IF($B35="","", SUMIFS('05 Cash Flow'!$G:$G, '05 Cash Flow'!$B:$B, $B35) * (1 + '02 Assumptions'!$B$5)) -> 18360 | D35: =IF($B35="","", C35 * (1 + '02 Assumptions'!$B$5)) -> 18727.2 | E35: =IF($B35="","", D35 * (1 + '02 Assumptions'!$B$5)) -> 19101.744 | F35: =IF($B35="","", E35 * (1 + '02 Assumptions'!$B$5)) -> 19483.779 | G35: =IF($B35="","", F35 * (1 + '02 Assumptions'!$B$5)) -> 19873.454 | H35: =IF($B35="","", G35 * (1 + '02 Assumptions'!$B$5)) -> 20270.924 | I35: =IF($B35="","", H35 * (1 + '02 Assumptions'!$B$5)) -> 20676.342 | J35: =IF($B35="","", I35 * (1 + '02 Assumptions'!$B$5)) -> 21089.869 | K35: =IF($B35="","", J35 * (1 + '02 Assumptions'!$B$5)) -> 21511.666 | ... M35: =IF($B35="","", L35 * (1 + '02 Assumptions'!$B$5)) -> 22380.738
